<?xml version="1.0"?>
<robot name="giraffe_robot">

  <!-- Base link (ceiling mounted) -->
  <link name="base_link">
    <inertial>
      <origin xyz="0 0 0" rpy="0 0 0"/>
      <mass value="1.0"/>
      <inertia ixx="0.01" ixy="0" ixz="0" iyy="0.01" iyz="0" izz="0.01"/>
    </inertial>
  </link>

  <!-- Joint 1: yaw -->
  <joint name="joint1_yaw" type="revolute">
    <parent link="base_link"/>
    <child link="yaw_link"/>
    <origin xyz="0 0 0" rpy="0 0 0"/>
    <axis xyz="0 0 1"/>
    <limit lower="-3.14" upper="3.14" effort="10.0" velocity="1.0"/>
  </joint>
  <link name="yaw_link"/>

  <!-- Joint 2: pitch -->
  <joint name="joint2_pitch" type="revolute">
    <parent link="yaw_link"/>
    <child link="shoulder_link"/>
    <origin xyz="0 0 0" rpy="0 0 0"/>
    <axis xyz="0 1 0"/>
    <limit lower="-1.57" upper="1.57" effort="10.0" velocity="1.0"/>
  </joint>
  <link name="shoulder_link"/>

  <!-- Joint 3: prismatic extension -->
  <joint name="joint3_extend" type="prismatic">
    <parent link="shoulder_link"/>
    <child link="neck_link"/>
    <origin xyz="0 0 0" rpy="0 0 0"/>
    <axis xyz="0 0 -1"/>
    <limit lower="0.0" upper="3.0" effort="50.0" velocity="0.5"/>
  </joint>
  <link name="neck_link">
    <visual>
      <origin xyz="0 0 -1.5" rpy="0 0 0"/>
      <geometry>
        <cylinder radius="0.05" length="3.0"/>
      </geometry>
      <material name="grey">
        <color rgba="0.6 0.6 0.6 1"/>
      </material>
    </visual>
    <inertial>
      <origin xyz="0 0 -1.5"/>
      <mass value="3.0"/>
      <inertia ixx="0.3" ixy="0" ixz="0" iyy="0.3" iyz="0" izz="0.1"/>
    </inertial>
  </link>

  <!-- Joint 4: mic pitch -->
  <joint name="joint4_pitch" type="revolute">
    <parent link="neck_link"/>
    <child link="wrist_link"/>
    <origin xyz="0 0 -3.0" rpy="0 0 0"/>
    <axis xyz="0 1 0"/>
    <limit lower="-1.57" upper="1.57" effort="5.0" velocity="1.0"/>
  </joint>
  <link name="wrist_link"/>

  <!-- Joint 5: mic roll -->
  <joint name="joint5_roll" type="revolute">
    <parent link="wrist_link"/>
    <child link="microphone_link"/>
    <origin xyz="0 0 0" rpy="0 0 0"/>
    <axis xyz="1 0 0"/>
    <limit lower="-1.57" upper="1.57" effort="5.0" velocity="1.0"/>
  </joint>

  <link name="microphone_link">
    <visual>
      <origin xyz="0 0 0.1" rpy="0 0 0"/>
      <geometry>
        <cylinder radius="0.02" length="0.2"/>
      </geometry>
      <material name="black">
        <color rgba="0.1 0.1 0.1 1.0"/>
      </material>
    </visual>
    <inertial>
      <origin xyz="0 0 0.1"/>
      <mass value="0.2"/>
      <inertia ixx="0.001" ixy="0" ixz="0" iyy="0.001" iyz="0" izz="0.001"/>
    </inertial>
  </link>

</robot>
